<?xml version="1.0"?>
<robot name="resto">

    <material name="blue">
        <color rgba="0 0 0.8 1"/>
    </material>
    <material name="red">
        <color rgba="0.8 0 0 1"/>
    </material>
    <material name="green">
        <color rgba="0 0.8 0 1"/>
    </material>
    <material name="grey">
        <color rgba="0.75 0.75 0.75 1"/>
    </material>
    <material name="white">
        <color rgba="1.0 1.0 1.0 1"/>
    </material>
    <material name="black">
        <color rgba="0 0 0 1"/>
    </material>

	<!-- * * * Link Definitions * * * -->
    <link name="base_link">
 	    <inertial>
            <origin xyz="0 0 0" rpy="0 0 0"/>
            <mass value="0.1" />
            <inertia iw="0.0002835" id="0.0" ih="0.0"/>
        </inertial>
        <collision>
            <origin rpy="0.0 0 0" xyz="0 0 0"/>
            <geometry>
                <box size="0.1 0.17 0.085"/>
            </geometry>
            <material name="grey"/>
        </collision>

        <visual>
            <origin rpy="0.0 0 0" xyz="0 0 0"/>
            <geometry>
                <box size="0.1 0.17 0.085"/>
            </geometry>
            <material name="grey"/>
        </visual>
	</link>

    <gazebo reference="base_link">
        <kp>100000.0</kp>
        <kd>100000.0</kd>
        <mu1>10.0</mu1>
        <mu2>10.0</mu2>
        <material>Gazebo/Grey</material>
    </gazebo>

    <link name="roll_M1_link">
        <visual>
            <origin rpy="0 0 0" xyz="0 0 0"/>
            <geometry>
                <cylinder length="0.005" radius="0.01"/>
            </geometry>
            <material name="red"/>
        </visual>
    </link>

    <joint name="roll_joint" type="revolute">
    	<parent link="base_link"/>
    	<child link="roll_M1_link"/>
        <origin xyz="0.0023 0 -0.0005" rpy="0 0 0"/>
        <limit lower="-0.2" upper="0.2" effort="0.1" velocity="0.005"/>
        <axis xyz="1 0 0"/>
	</joint>

    <link name="pitch_M2_link">
        <visual>
            <origin rpy="0 0 0" xyz="0 0 0"/>
            <geometry>
                <cylinder length="0.005" radius="0.01"/>
            </geometry>
            <material name="green"/>
        </visual>
    </link>


    <joint name="pitch_joint" type="revolute">
    	<parent link="roll_M1_link"/>
    	<child link="pitch_M2_link"/>
    	<origin xyz="0 0 0" rpy="0 -1.5708 0"/>
        <limit lower="0" upper="0.44" effort="0.1" velocity="0.005"/>
        <axis xyz="0 1 0"/>
	</joint>


    <link name="yaw_M3_link">
        <visual>
            <origin rpy="0 0 0" xyz="0 0 0"/>
            <geometry>
                <cylinder length="0.005" radius="0.01"/>
            </geometry>
            <material name="blue"/>
        </visual>
    </link>

    <joint name="yaw_joint" type="continuous">
    	<parent link="pitch_M2_link"/>
    	<child link="yaw_M3_link"/>
        <origin xyz="0.01 0 0" rpy="0 1.5708 0"/>
        <limit effort="0.1" velocity="0.01"/>
        <axis xyz="0 0 1"/>
	</joint>

    <link name="left_eye_link">
		<visual>
            <origin rpy="0.0 0 0" xyz="0 0 0"/>
            <geometry>
                <box size="0.026 0.015 0.006"/>
            </geometry>
            <material name="black"/>
        </visual>
	</link>

    <link name="right_eye_link">
		<visual>
            <origin rpy="0.0 0 0" xyz="0 0 0"/>
            <geometry>
                <box size="0.026 0.015 0.006"/>
            </geometry>
            <material name="black"/>
        </visual>
	</link>

    <joint name="lefteye_joint" type="fixed">
        <parent link="base_link"/>
        <child link="left_eye_link"/>
        <origin xyz="0.037 0.088 0.0085" rpy="-1.5708 0 0"/>
    </joint>

    <joint name="righteye_joint" type="fixed">
        <parent link="base_link"/>
        <child link="right_eye_link"/>
        <origin xyz="-0.037 0.088 0.0085" rpy="-1.5708 0 0"/>
    </joint>

    <link name="front_left_wheel">
		<visual>
            <origin rpy="0.0 0 0" xyz="0 0 0"/>
            <geometry>
                <cylinder length="0.013" radius="0.017"/>
            </geometry>
            <material name="black"/>
        </visual>
	</link>

    <joint name="front_left_wheel_joint" type="fixed">
        <parent link="base_link"/>
        <child link="front_left_wheel"/>
        <origin xyz="0.057 0.052 -0.045" rpy="-1.5708 0 -1.5708"/>
    </joint>

    <link name="front_right_wheel">
		<visual>
            <origin rpy="0.0 0 0" xyz="0 0 0"/>
            <geometry>
                <cylinder length="0.013" radius="0.017"/>
            </geometry>
            <material name="black"/>
        </visual>
	</link>

    <joint name="front_right_wheel_joint" type="fixed">
        <parent link="base_link"/>
        <child link="front_right_wheel"/>
        <origin xyz="-0.057 0.052 -0.045" rpy="-1.5708 0 -1.5708"/>
    </joint>

    <link name="back_left_wheel">
		<visual>
            <origin rpy="0.0 0 0" xyz="0 0 0"/>
            <geometry>
                <cylinder length="0.013" radius="0.017"/>
            </geometry>
            <material name="black"/>
        </visual>
	</link>

    <joint name="back_left_wheel_joint" type="fixed">
        <parent link="base_link"/>
        <child link="back_left_wheel"/>
        <origin xyz="0.057 -0.052 -0.045" rpy="-1.5708 0 -1.5708"/>
    </joint>

    <link name="back_right_wheel">
		<visual>
            <origin rpy="0.0 0 0" xyz="0 0 0"/>
            <geometry>
                <cylinder length="0.013" radius="0.017"/>
            </geometry>
            <material name="black"/>
        </visual>
	</link>

    <joint name="back_right_wheel_joint" type="fixed">
        <parent link="base_link"/>
        <child link="back_right_wheel"/>
        <origin xyz="-0.057 -0.052 -0.045" rpy="-1.5708 0 -1.5708"/>
    </joint>

</robot>
